Traceback (most recent call last):
  File "/usr/local/lib/python3.10/dist-packages/jupyter_cache/executors/utils.py", line 58, in single_nb_execution
    executenb(
  File "/usr/local/lib/python3.10/dist-packages/nbclient/client.py", line 1305, in execute
    return NotebookClient(nb=nb, resources=resources, km=km, **kwargs).execute()
  File "/usr/local/lib/python3.10/dist-packages/jupyter_core/utils/__init__.py", line 173, in wrapped
    return loop.run_until_complete(inner)
  File "/usr/lib/python3.10/asyncio/base_events.py", line 649, in run_until_complete
    return future.result()
  File "/usr/local/lib/python3.10/dist-packages/nbclient/client.py", line 705, in async_execute
    await self.async_execute_cell(
  File "/usr/local/lib/python3.10/dist-packages/nbclient/client.py", line 1058, in async_execute_cell
    await self._check_raise_for_error(cell, cell_index, exec_reply)
  File "/usr/local/lib/python3.10/dist-packages/nbclient/client.py", line 914, in _check_raise_for_error
    raise CellExecutionError.from_cell_and_msg(cell, exec_reply_content)
nbclient.exceptions.CellExecutionError: An error occurred while executing the following cell:
------------------
import os

%cd /content/
os.mkdir('data_berita')

import gdown
# download data

nama_data = '/content/data_berita/data_berita.csv'
gdown.download(f'https://drive.google.com/uc?id=1vu67IeDIAWTCH9hk4C39DrH9JKXHpUVi', nama_data, quiet=False)
------------------

----- stdout -----
/content
------------------

[0;31m---------------------------------------------------------------------------[0m
[0;31mFileExistsError[0m                           Traceback (most recent call last)
[0;32m<ipython-input-1-c8125b64ee4c>[0m in [0;36m<cell line: 4>[0;34m()[0m
[1;32m      2[0m [0;34m[0m[0m
[1;32m      3[0m [0mget_ipython[0m[0;34m([0m[0;34m)[0m[0;34m.[0m[0mrun_line_magic[0m[0;34m([0m[0;34m'cd'[0m[0;34m,[0m [0;34m'/content/'[0m[0;34m)[0m[0;34m[0m[0;34m[0m[0m
[0;32m----> 4[0;31m [0mos[0m[0;34m.[0m[0mmkdir[0m[0;34m([0m[0;34m'data_berita'[0m[0;34m)[0m[0;34m[0m[0;34m[0m[0m
[0m[1;32m      5[0m [0;34m[0m[0m
[1;32m      6[0m [0;32mimport[0m [0mgdown[0m[0;34m[0m[0;34m[0m[0m

[0;31mFileExistsError[0m: [Errno 17] File exists: 'data_berita'

